<?xml version="1.0"?>
<!--
	Space Robotics Challenge Phase 2
	NASA-JSC
	Copyright (c) 2020, All Rights Reserved
	Unauthorized distribution strictly prohibited
-->


<!--
    @brief the small-scout's volatile sensor
    This is largely a cosmetic attachement, and something to hang the
    volatile sensor link off
-->
<robot xmlns:xacro="http://ros.org/wiki/xacro">

    <xacro:macro name="volatile_sensor" params="rover_name">

        <xacro:macro name="volatile_sensor_mount_origin">
            <origin
                xyz="0 0 0"
                rpy="0 0 0"/>
        </xacro:macro>
        <xacro:macro name="volatile_sensor_origin">
            <origin
                xyz="0 0 -0.19"
                rpy="0 0 0"/>
        </xacro:macro>

        <link name="$(arg rover_name)_volatile_sensor_mount">

            <collision name="$(arg rover_name)_volatile_sensor_mount_collision">
                <xacro:volatile_sensor_mount_origin/>
                <geometry>
                    <cylinder radius="0.1" length="0.1"/>
                </geometry>
            </collision>

             <visual name="$(arg rover_name)_volatile_sensor_mount_visual">
                <origin
                    xyz="-0.59 0 -0.05"
                    rpy="0 0 ${pi/2.0}"/>
                <geometry>
                    <mesh
                        filename = "package://srcp2_models_final/meshes/rovers/small_scout/volatile_sensor.dae"
                        scale    = "0.37 0.37 0.37"/>
                </geometry>
            </visual>

            <inertial>
                <xacro:volatile_sensor_mount_origin/>
                <mass value="2.0"/>
                <xacro:cylinder_inertia
                    m="2.0"
                    r="0.1"
                    h="0.1"/>
            </inertial>
        </link>

        <!-- this is the part we reference for scoring and volatile detection -->
        <link name="$(arg rover_name)_volatile_sensor">
            <collision name="$(arg rover_name)_volatile_sensor_collision">
                <xacro:volatile_sensor_origin/>
                <geometry>
                    <cylinder radius="0.025" length="0.01"/>
                </geometry>
            </collision>
            <inertial>
                <xacro:volatile_sensor_mount_origin/>
                <mass value="0.1"/>
                <xacro:cylinder_inertia
                    m="0.1"
                    r="0.025"
                    h="0.01"/>
            </inertial>
        </link>

        <!-- bolt the sensor box to the chassis -->
        <joint name="volatile_sensor_mount_joint" type="fixed">
            <origin xyz="0.67 0.0 -0.1" rpy="0 0 0"/>
            <parent link = "$(arg rover_name)_small_chassis" />
            <child  link = "$(arg rover_name)_volatile_sensor_mount"/>
        </joint>

        <!-- fix the sensor tip to the sensor body. This is a revolute joint to 
             keep it from being integrated into the chassis, but it does not
             really turn -->
        <joint name="volatile_sensor_joint" type="revolute">
            <origin xyz="0.0 0.0 0.0" rpy="0 0 0"/>
            <parent link = "$(arg rover_name)_volatile_sensor_mount"/>
            <child  link = "$(arg rover_name)_volatile_sensor"/>
            <axis xyz="1 0 0" rpy="0 0 0"/>
             <limit
                upper    = "0.01" 
                lower    = "-0.01" 
                effort   = "1e9" 
                velocity = "0.01"/>
            <dynamics
                damping  = "1"
                friction = "0.5"/>                
        </joint>

        <gazebo reference='volatile_sensor_joint'>
            <preserveFixedJoint>true</preserveFixedJoint>
        </gazebo>

        <gazebo reference='volatile_sensor_mount_joint'>
            <preserveFixedJoint>true</preserveFixedJoint>
        </gazebo>

        <!--gazebo lib -->
        <gazebo>
            <plugin filename="libVolatileSensor.so" name="VolatileSensorPlugin">
                <publish_interval>5.0</publish_interval>
                <publish_inrange_only>false</publish_inrange_only>
                <sensor_topic>volatile_sensor</sensor_topic>
                <sensing_range>2.0</sensing_range>
                <min_volatile_depth>5.0</min_volatile_depth>
                <max_volatile_depth>20.0</max_volatile_depth>
                <sensor_link>$(arg rover_name)_volatile_sensor</sensor_link>
            </plugin>
        </gazebo>


    </xacro:macro>
</robot>